Workbook

Sheet README
A1: Sport Profile Database — v1.5
A3: Purpose
A4: Reference dataset of elite-athlete anthropometric and performance profiles, used as the basis for matching users to sports based on body measurements and preferences. Built to be expanded to 40–60 sports before any matching logic is written.
A6: Sheets
A7: • Profiles — one row per sport (or position). Mean and SD where available. All numeric cells should cite a source via the Source ID column.
A8: • Sources — bibliography. Every numeric figure on Profiles refers back to a Source ID here.
A9: • Schema notes — definitions and scoring conventions for each column.
A10: • Scoring weights — placeholder for the matching model. Not used yet.
A12: Conventions
A13: • Units: cm for height/wingspan, kg for weight, % for body fat. Always SI.
A14: • Mean ± SD where the source provides it. Single values where only a mean is reported.
A15: • Demand scores (aerobic, anaerobic, strength, power, etc.) are 1–10 estimates assigned from the literature. These are subjective and the first thing to revisit once the model is tested.
... A41: v1.5 — bug fix: corrected the sex tag on three female-only sport rows that were wrongly marked M (gymnastics SP07, netball SP42, netball SP42b). The v1.2 sex-tagging logic only flagged F based on ID suffix or a narrow hardcoded name list, so these slipped through.

Sheet User Input
A1: User Input — fill in the BLUE cells
A2: Yellow background = editable. Blue text = your data. The Scoring sheet recalculates automatically.
A4: Identity & demographics
A6: Sex (M / F) | B6: M | C6: Hard filter — only sports rows matching this sex (or unisex-coded) are returned.
A7: Archetype (endurance / strength / explosive / skill / balanced / untrained) | B7: balanced | C7: Replaces 8 self-rated ability scores. Pick: endurance / strength / explosive / skill / balanced / untrained.
A8: Body measurements
A9: Height (cm) | B9: 183 | C9: Standing height without shoes.
A10: Weight (kg) | B10: 88 | C10: Current body weight.
A11: BMI (auto) | B11: =B10/((B9/100)^2) | C11: Auto-calculated from height and weight.
A12: Body fat % (estimate) | B12: 14 | C12: Best estimate — skinfold, BIA, or visual estimate.
A13: Wingspan (cm, optional) | B13: 188 | C13: Arm span — fingertip to fingertip. Leave blank if not measured (will fall back to height).
A14: Wingspan / height ratio (auto) | B14: =IF(B13="",1,B13/B9) | C14: Auto-calculated. 1.0 = wingspan equals height. NBA average is 1.063.
A16: Derived demand profile (from archetype — do not edit)
A17: Aerobic endurance | B17: =IFERROR(INDEX($B$47:$I$52,MATCH($B$7,$A$47:$A$52,0),1),5) | C17: Auto-derived from archetype. Do not edit.
A18: Anaerobic capacity | B18: =IFERROR(INDEX($B$47:$I$52,MATCH($B$7,$A$47:$A$52,0),2),5) | C18: Auto-derived from archetype. Do not edit.
A19: Max strength | B19: =IFERROR(INDEX($B$47:$I$52,MATCH($B$7,$A$47:$A$52,0),3),5) | C19: Auto-derived from archetype. Do not edit.
A20: Explosive power | B20: =IFERROR(INDEX($B$47:$I$52,MATCH($B$7,$A$47:$A$52,0),4),5) | C20: Auto-derived from archetype. Do not edit.
A21: Pure speed | B21: =IFERROR(INDEX($B$47:$I$52,MATCH($B$7,$A$47:$A$52,0),5),5) | C21: Auto-derived from archetype. Do not edit.
A22: Flexibility / mobility | B22: =IFERROR(INDEX($B$47:$I$52,MATCH($B$7,$A$47:$A$52,0),6),5) | C22: Auto-derived from archetype. Do not edit.
A23: Coordination / skill | B23: =IFERROR(INDEX($B$47:$I$52,MATCH($B$7,$A$47:$A$52,0),7),5) | C23: Auto-derived from archetype. Do not edit.
A24: Reaction time | B24: =IFERROR(INDEX($B$47:$I$52,MATCH($B$7,$A$47:$A$52,0),8),5) | C24: Auto-derived from archetype. Do not edit.
A26: Preferences & constraints
A27: Team vs solo preference (Team / Solo / Either) | B27: Team | C27: Hard preference. 'Either' opens up both.
A28: Contact tolerance (None / Light / Medium / Heavy) | B28: Heavy | C28: Maximum contact you're happy with. Sports exceeding this are penalised.
A29: Outdoor importance (essential / nice / neutral / indoor) | B29: nice | C29: "essential" = must be outdoor; "nice" = prefer outdoor; "neutral" = no preference; "indoor" = prefer indoor.
A30: Comfortable in water? (Yes / No) | B30: Yes | C30: If No, all water-based sports are excluded.
A31: Budget for equipment (Low / Medium / High) | B31: Medium | C31: Low <€200, Medium €200–1000, High >€1000 to start. Sports exceeding budget are penalised.
A32: Ireland-based? (Yes / No) | B32: Yes | C32: If Yes, the Ireland-accessibility weight kicks in.
A33: Experience (none / short / medium / long) | B33: medium | C33: "none"=never competed; "short"=under 2y; "medium"=2-5y; "long"=over 5y. Sports requiring childhood entry get 0.7x enjoyment for "none".
A34: Sports enjoyed — team_field? (Yes/No) | B34: No | C34: Yes = 15% enjoyment boost for sports in this category. (GAA, soccer, rugby, hockey, AFL)
A35: Sports enjoyed — team_court? (Yes/No) | B35: No | C35: Yes = 15% enjoyment boost for sports in this category. (Basketball, volleyball, netball)
A36: Sports enjoyed — racquet? (Yes/No) | B36: No | C36: Yes = 15% enjoyment boost for sports in this category. (Tennis, badminton, squash, table tennis)
A37: Sports enjoyed — combat? (Yes/No) | B37: No | C37: Yes = 15% enjoyment boost for sports in this category. (Boxing, MMA, wrestling, judo, taekwondo)
A38: Sports enjoyed — water? (Yes/No) | B38: No | C38: Yes = 15% enjoyment boost for sports in this category. (Swimming, surfing, sailing, water polo)
... A41: Sports enjoyed — technical? (Yes/No) | B41: No | C41: Yes = 15% enjoyment boost for sports in this category. (Climbing, gymnastics, dance, archery)
A42: Age group (under30 / 30to45 / 46to60 / 61plus) | B42: under30
A43: Injury status (none / minor / joint / significant) | B43: none
A45: Archetype demand lookup table (read-only reference)
A46: Archetype | B46: Aerobic | C46: Anaerobic | D46: Max strength | E46: Power | F46: Speed | G46: Flexibility | H46: Coordination | I46: Reaction
A47: endurance | B47: 9 | C47: 7 | D47: 4 | E47: 5 | F47: 6 | G47: 5 | H47: 6 | I47: 5
...

Sheet Built For
A1: Sports your body is built for
A2: Ranked by physiological fit — your measurements vs elite-athlete profiles. May surface sports you've never considered.
A4: # | B4: Sport | C4: Position / Discipline | D4: Category | E4: Built-for | F4: Enjoyment
A5: 1 | B5: =INDEX(Scoring!$B:$B,MATCH($H$5,Scoring!$T$2:$T$112,0)+1) | C5: =INDEX(Scoring!$C:$C,MATCH($H$5,Scoring!$T$2:$T$112,0)+1) | D5: =INDEX(Scoring!$D:$D,MATCH($H$5,Scoring!$T$2:$T$112,0)+1) | E5: =INDEX(Scoring!$J:$J,MATCH($H$5,Scoring!$T$2:$T$112,0)+1) | F5: =INDEX(Scoring!$R:$R,MATCH($H$5,Scoring!$T$2:$T$112,0)+1) | H5: =LARGE(Scoring!$T$2:$T$112,1)
A6: 2 | B6: =INDEX(Scoring!$B:$B,MATCH($H$6,Scoring!$T$2:$T$112,0)+1) | C6: =INDEX(Scoring!$C:$C,MATCH($H$6,Scoring!$T$2:$T$112,0)+1) | D6: =INDEX(Scoring!$D:$D,MATCH($H$6,Scoring!$T$2:$T$112,0)+1) | E6: =INDEX(Scoring!$J:$J,MATCH($H$6,Scoring!$T$2:$T$112,0)+1) | F6: =INDEX(Scoring!$R:$R,MATCH($H$6,Scoring!$T$2:$T$112,0)+1) | H6: =LARGE(Scoring!$T$2:$T$112,2)
A7: 3 | B7: =INDEX(Scoring!$B:$B,MATCH($H$7,Scoring!$T$2:$T$112,0)+1) | C7: =INDEX(Scoring!$C:$C,MATCH($H$7,Scoring!$T$2:$T$112,0)+1) | D7: =INDEX(Scoring!$D:$D,MATCH($H$7,Scoring!$T$2:$T$112,0)+1) | E7: =INDEX(Scoring!$J:$J,MATCH($H$7,Scoring!$T$2:$T$112,0)+1) | F7: =INDEX(Scoring!$R:$R,MATCH($H$7,Scoring!$T$2:$T$112,0)+1) | H7: =LARGE(Scoring!$T$2:$T$112,3)
A8: 4 | B8: =INDEX(Scoring!$B:$B,MATCH($H$8,Scoring!$T$2:$T$112,0)+1) | C8: =INDEX(Scoring!$C:$C,MATCH($H$8,Scoring!$T$2:$T$112,0)+1) | D8: =INDEX(Scoring!$D:$D,MATCH($H$8,Scoring!$T$2:$T$112,0)+1) | E8: =INDEX(Scoring!$J:$J,MATCH($H$8,Scoring!$T$2:$T$112,0)+1) | F8: =INDEX(Scoring!$R:$R,MATCH($H$8,Scoring!$T$2:$T$112,0)+1) | H8: =LARGE(Scoring!$T$2:$T$112,4)
A9: 5 | B9: =INDEX(Scoring!$B:$B,MATCH($H$9,Scoring!$T$2:$T$112,0)+1) | C9: =INDEX(Scoring!$C:$C,MATCH($H$9,Scoring!$T$2:$T$112,0)+1) | D9: =INDEX(Scoring!$D:$D,MATCH($H$9,Scoring!$T$2:$T$112,0)+1) | E9: =INDEX(Scoring!$J:$J,MATCH($H$9,Scoring!$T$2:$T$112,0)+1) | F9: =INDEX(Scoring!$R:$R,MATCH($H$9,Scoring!$T$2:$T$112,0)+1) | H9: =LARGE(Scoring!$T$2:$T$112,5)
A10: 6 | B10: =INDEX(Scoring!$B:$B,MATCH($H$10,Scoring!$T$2:$T$112,0)+1) | C10: =INDEX(Scoring!$C:$C,MATCH($H$10,Scoring!$T$2:$T$112,0)+1) | D10: =INDEX(Scoring!$D:$D,MATCH($H$10,Scoring!$T$2:$T$112,0)+1) | E10: =INDEX(Scoring!$J:$J,MATCH($H$10,Scoring!$T$2:$T$112,0)+1) | F10: =INDEX(Scoring!$R:$R,MATCH($H$10,Scoring!$T$2:$T$112,0)+1) | H10: =LARGE(Scoring!$T$2:$T$112,6)
A11: 7 | B11: =INDEX(Scoring!$B:$B,MATCH($H$11,Scoring!$T$2:$T$112,0)+1) | C11: =INDEX(Scoring!$C:$C,MATCH($H$11,Scoring!$T$2:$T$112,0)+1) | D11: =INDEX(Scoring!$D:$D,MATCH($H$11,Scoring!$T$2:$T$112,0)+1) | E11: =INDEX(Scoring!$J:$J,MATCH($H$11,Scoring!$T$2:$T$112,0)+1) | F11: =INDEX(Scoring!$R:$R,MATCH($H$11,Scoring!$T$2:$T$112,0)+1) | H11: =LARGE(Scoring!$T$2:$T$112,7)
A12: 8 | B12: =INDEX(Scoring!$B:$B,MATCH($H$12,Scoring!$T$2:$T$112,0)+1) | C12: =INDEX(Scoring!$C:$C,MATCH($H$12,Scoring!$T$2:$T$112,0)+1) | D12: =INDEX(Scoring!$D:$D,MATCH($H$12,Scoring!$T$2:$T$112,0)+1) | E12: =INDEX(Scoring!$J:$J,MATCH($H$12,Scoring!$T$2:$T$112,0)+1) | F12: =INDEX(Scoring!$R:$R,MATCH($H$12,Scoring!$T$2:$T$112,0)+1) | H12: =LARGE(Scoring!$T$2:$T$112,8)
A13: 9 | B13: =INDEX(Scoring!$B:$B,MATCH($H$13,Scoring!$T$2:$T$112,0)+1) | C13: =INDEX(Scoring!$C:$C,MATCH($H$13,Scoring!$T$2:$T$112,0)+1) | D13: =INDEX(Scoring!$D:$D,MATCH($H$13,Scoring!$T$2:$T$112,0)+1) | E13: =INDEX(Scoring!$J:$J,MATCH($H$13,Scoring!$T$2:$T$112,0)+1) | F13: =INDEX(Scoring!$R:$R,MATCH($H$13,Scoring!$T$2:$T$112,0)+1) | H13: =LARGE(Scoring!$T$2:$T$112,9)
A14: 10 | B14: =INDEX(Scoring!$B:$B,MATCH($H$14,Scoring!$T$2:$T$112,0)+1) | C14: =INDEX(Scoring!$C:$C,MATCH($H$14,Scoring!$T$2:$T$112,0)+1) | D14: =INDEX(Scoring!$D:$D,MATCH($H$14,Scoring!$T$2:$T$112,0)+1) | E14: =INDEX(Scoring!$J:$J,MATCH($H$14,Scoring!$T$2:$T$112,0)+1) | F14: =INDEX(Scoring!$R:$R,MATCH($H$14,Scoring!$T$2:$T$112,0)+1) | H14: =LARGE(Scoring!$T$2:$T$112,10)
A15: 11 | B15: =INDEX(Scoring!$B:$B,MATCH($H$15,Scoring!$T$2:$T$112,0)+1) | C15: =INDEX(Scoring!$C:$C,MATCH($H$15,Scoring!$T$2:$T$112,0)+1) | D15: =INDEX(Scoring!$D:$D,MATCH($H$15,Scoring!$T$2:$T$112,0)+1) | E15: =INDEX(Scoring!$J:$J,MATCH($H$15,Scoring!$T$2:$T$112,0)+1) | F15: =INDEX(Scoring!$R:$R,MATCH($H$15,Scoring!$T$2:$T$112,0)+1) | H15: =LARGE(Scoring!$T$2:$T$112,11)
A16: 12 | B16: =INDEX(Scoring!$B:$B,MATCH($H$16,Scoring!$T$2:$T$112,0)+1) | C16: =INDEX(Scoring!$C:$C,MATCH($H$16,Scoring!$T$2:$T$112,0)+1) | D16: =INDEX(Scoring!$D:$D,MATCH($H$16,Scoring!$T$2:$T$112,0)+1) | E16: =INDEX(Scoring!$J:$J,MATCH($H$16,Scoring!$T$2:$T$112,0)+1) | F16: =INDEX(Scoring!$R:$R,MATCH($H$16,Scoring!$T$2:$T$112,0)+1) | H16: =LARGE(Scoring!$T$2:$T$112,12)
A17: 13 | B17: =INDEX(Scoring!$B:$B,MATCH($H$17,Scoring!$T$2:$T$112,0)+1) | C17: =INDEX(Scoring!$C:$C,MATCH($H$17,Scoring!$T$2:$T$112,0)+1) | D17: =INDEX(Scoring!$D:$D,MATCH($H$17,Scoring!$T$2:$T$112,0)+1) | E17: =INDEX(Scoring!$J:$J,MATCH($H$17,Scoring!$T$2:$T$112,0)+1) | F17: =INDEX(Scoring!$R:$R,MATCH($H$17,Scoring!$T$2:$T$112,0)+1) | H17: =LARGE(Scoring!$T$2:$T$112,13)
A18: 14 | B18: =INDEX(Scoring!$B:$B,MATCH($H$18,Scoring!$T$2:$T$112,0)+1) | C18: =INDEX(Scoring!$C:$C,MATCH($H$18,Scoring!$T$2:$T$112,0)+1) | D18: =INDEX(Scoring!$D:$D,MATCH($H$18,Scoring!$T$2:$T$112,0)+1) | E18: =INDEX(Scoring!$J:$J,MATCH($H$18,Scoring!$T$2:$T$112,0)+1) | F18: =INDEX(Scoring!$R:$R,MATCH($H$18,Scoring!$T$2:$T$112,0)+1) | H18: =LARGE(Scoring!$T$2:$T$112,14)
A19: 15 | B19: =INDEX(Scoring!$B:$B,MATCH($H$19,Scoring!$T$2:$T$112,0)+1) | C19: =INDEX(Scoring!$C:$C,MATCH($H$19,Scoring!$T$2:$T$112,0)+1) | D19: =INDEX(Scoring!$D:$D,MATCH($H$19,Scoring!$T$2:$T$112,0)+1) | E19: =INDEX(Scoring!$J:$J,MATCH($H$19,Scoring!$T$2:$T$112,0)+1) | F19: =INDEX(Scoring!$R:$R,MATCH($H$19,Scoring!$T$2:$T$112,0)+1) | H19: =LARGE(Scoring!$T$2:$T$112,15)
A21: ↑ Live — these rankings recalculate when you edit the User Input sheet.

Sheet You'd Enjoy
A1: Sports you'd probably enjoy most
A2: Ranked by preference fit — your stated likes vs sport characteristics. Reflects what you've told us you want.
A4: # | B4: Sport | C4: Position / Discipline | D4: Category | E4: Enjoyment | F4: Built-for
A5: 1 | B5: =INDEX(Scoring!$B:$B,MATCH($H$5,Scoring!$U$2:$U$112,0)+1) | C5: =INDEX(Scoring!$C:$C,MATCH($H$5,Scoring!$U$2:$U$112,0)+1) | D5: =INDEX(Scoring!$D:$D,MATCH($H$5,Scoring!$U$2:$U$112,0)+1) | E5: =INDEX(Scoring!$R:$R,MATCH($H$5,Scoring!$U$2:$U$112,0)+1) | F5: =INDEX(Scoring!$J:$J,MATCH($H$5,Scoring!$U$2:$U$112,0)+1) | H5: =LARGE(Scoring!$U$2:$U$112,1)
A6: 2 | B6: =INDEX(Scoring!$B:$B,MATCH($H$6,Scoring!$U$2:$U$112,0)+1) | C6: =INDEX(Scoring!$C:$C,MATCH($H$6,Scoring!$U$2:$U$112,0)+1) | D6: =INDEX(Scoring!$D:$D,MATCH($H$6,Scoring!$U$2:$U$112,0)+1) | E6: =INDEX(Scoring!$R:$R,MATCH($H$6,Scoring!$U$2:$U$112,0)+1) | F6: =INDEX(Scoring!$J:$J,MATCH($H$6,Scoring!$U$2:$U$112,0)+1) | H6: =LARGE(Scoring!$U$2:$U$112,2)
A7: 3 | B7: =INDEX(Scoring!$B:$B,MATCH($H$7,Scoring!$U$2:$U$112,0)+1) | C7: =INDEX(Scoring!$C:$C,MATCH($H$7,Scoring!$U$2:$U$112,0)+1) | D7: =INDEX(Scoring!$D:$D,MATCH($H$7,Scoring!$U$2:$U$112,0)+1) | E7: =INDEX(Scoring!$R:$R,MATCH($H$7,Scoring!$U$2:$U$112,0)+1) | F7: =INDEX(Scoring!$J:$J,MATCH($H$7,Scoring!$U$2:$U$112,0)+1) | H7: =LARGE(Scoring!$U$2:$U$112,3)
A8: 4 | B8: =INDEX(Scoring!$B:$B,MATCH($H$8,Scoring!$U$2:$U$112,0)+1) | C8: =INDEX(Scoring!$C:$C,MATCH($H$8,Scoring!$U$2:$U$112,0)+1) | D8: =INDEX(Scoring!$D:$D,MATCH($H$8,Scoring!$U$2:$U$112,0)+1) | E8: =INDEX(Scoring!$R:$R,MATCH($H$8,Scoring!$U$2:$U$112,0)+1) | F8: =INDEX(Scoring!$J:$J,MATCH($H$8,Scoring!$U$2:$U$112,0)+1) | H8: =LARGE(Scoring!$U$2:$U$112,4)
A9: 5 | B9: =INDEX(Scoring!$B:$B,MATCH($H$9,Scoring!$U$2:$U$112,0)+1) | C9: =INDEX(Scoring!$C:$C,MATCH($H$9,Scoring!$U$2:$U$112,0)+1) | D9: =INDEX(Scoring!$D:$D,MATCH($H$9,Scoring!$U$2:$U$112,0)+1) | E9: =INDEX(Scoring!$R:$R,MATCH($H$9,Scoring!$U$2:$U$112,0)+1) | F9: =INDEX(Scoring!$J:$J,MATCH($H$9,Scoring!$U$2:$U$112,0)+1) | H9: =LARGE(Scoring!$U$2:$U$112,5)
A10: 6 | B10: =INDEX(Scoring!$B:$B,MATCH($H$10,Scoring!$U$2:$U$112,0)+1) | C10: =INDEX(Scoring!$C:$C,MATCH($H$10,Scoring!$U$2:$U$112,0)+1) | D10: =INDEX(Scoring!$D:$D,MATCH($H$10,Scoring!$U$2:$U$112,0)+1) | E10: =INDEX(Scoring!$R:$R,MATCH($H$10,Scoring!$U$2:$U$112,0)+1) | F10: =INDEX(Scoring!$J:$J,MATCH($H$10,Scoring!$U$2:$U$112,0)+1) | H10: =LARGE(Scoring!$U$2:$U$112,6)
A11: 7 | B11: =INDEX(Scoring!$B:$B,MATCH($H$11,Scoring!$U$2:$U$112,0)+1) | C11: =INDEX(Scoring!$C:$C,MATCH($H$11,Scoring!$U$2:$U$112,0)+1) | D11: =INDEX(Scoring!$D:$D,MATCH($H$11,Scoring!$U$2:$U$112,0)+1) | E11: =INDEX(Scoring!$R:$R,MATCH($H$11,Scoring!$U$2:$U$112,0)+1) | F11: =INDEX(Scoring!$J:$J,MATCH($H$11,Scoring!$U$2:$U$112,0)+1) | H11: =LARGE(Scoring!$U$2:$U$112,7)
A12: 8 | B12: =INDEX(Scoring!$B:$B,MATCH($H$12,Scoring!$U$2:$U$112,0)+1) | C12: =INDEX(Scoring!$C:$C,MATCH($H$12,Scoring!$U$2:$U$112,0)+1) | D12: =INDEX(Scoring!$D:$D,MATCH($H$12,Scoring!$U$2:$U$112,0)+1) | E12: =INDEX(Scoring!$R:$R,MATCH($H$12,Scoring!$U$2:$U$112,0)+1) | F12: =INDEX(Scoring!$J:$J,MATCH($H$12,Scoring!$U$2:$U$112,0)+1) | H12: =LARGE(Scoring!$U$2:$U$112,8)
A13: 9 | B13: =INDEX(Scoring!$B:$B,MATCH($H$13,Scoring!$U$2:$U$112,0)+1) | C13: =INDEX(Scoring!$C:$C,MATCH($H$13,Scoring!$U$2:$U$112,0)+1) | D13: =INDEX(Scoring!$D:$D,MATCH($H$13,Scoring!$U$2:$U$112,0)+1) | E13: =INDEX(Scoring!$R:$R,MATCH($H$13,Scoring!$U$2:$U$112,0)+1) | F13: =INDEX(Scoring!$J:$J,MATCH($H$13,Scoring!$U$2:$U$112,0)+1) | H13: =LARGE(Scoring!$U$2:$U$112,9)
A14: 10 | B14: =INDEX(Scoring!$B:$B,MATCH($H$14,Scoring!$U$2:$U$112,0)+1) | C14: =INDEX(Scoring!$C:$C,MATCH($H$14,Scoring!$U$2:$U$112,0)+1) | D14: =INDEX(Scoring!$D:$D,MATCH($H$14,Scoring!$U$2:$U$112,0)+1) | E14: =INDEX(Scoring!$R:$R,MATCH($H$14,Scoring!$U$2:$U$112,0)+1) | F14: =INDEX(Scoring!$J:$J,MATCH($H$14,Scoring!$U$2:$U$112,0)+1) | H14: =LARGE(Scoring!$U$2:$U$112,10)
A15: 11 | B15: =INDEX(Scoring!$B:$B,MATCH($H$15,Scoring!$U$2:$U$112,0)+1) | C15: =INDEX(Scoring!$C:$C,MATCH($H$15,Scoring!$U$2:$U$112,0)+1) | D15: =INDEX(Scoring!$D:$D,MATCH($H$15,Scoring!$U$2:$U$112,0)+1) | E15: =INDEX(Scoring!$R:$R,MATCH($H$15,Scoring!$U$2:$U$112,0)+1) | F15: =INDEX(Scoring!$J:$J,MATCH($H$15,Scoring!$U$2:$U$112,0)+1) | H15: =LARGE(Scoring!$U$2:$U$112,11)
A16: 12 | B16: =INDEX(Scoring!$B:$B,MATCH($H$16,Scoring!$U$2:$U$112,0)+1) | C16: =INDEX(Scoring!$C:$C,MATCH($H$16,Scoring!$U$2:$U$112,0)+1) | D16: =INDEX(Scoring!$D:$D,MATCH($H$16,Scoring!$U$2:$U$112,0)+1) | E16: =INDEX(Scoring!$R:$R,MATCH($H$16,Scoring!$U$2:$U$112,0)+1) | F16: =INDEX(Scoring!$J:$J,MATCH($H$16,Scoring!$U$2:$U$112,0)+1) | H16: =LARGE(Scoring!$U$2:$U$112,12)
A17: 13 | B17: =INDEX(Scoring!$B:$B,MATCH($H$17,Scoring!$U$2:$U$112,0)+1) | C17: =INDEX(Scoring!$C:$C,MATCH($H$17,Scoring!$U$2:$U$112,0)+1) | D17: =INDEX(Scoring!$D:$D,MATCH($H$17,Scoring!$U$2:$U$112,0)+1) | E17: =INDEX(Scoring!$R:$R,MATCH($H$17,Scoring!$U$2:$U$112,0)+1) | F17: =INDEX(Scoring!$J:$J,MATCH($H$17,Scoring!$U$2:$U$112,0)+1) | H17: =LARGE(Scoring!$U$2:$U$112,13)
A18: 14 | B18: =INDEX(Scoring!$B:$B,MATCH($H$18,Scoring!$U$2:$U$112,0)+1) | C18: =INDEX(Scoring!$C:$C,MATCH($H$18,Scoring!$U$2:$U$112,0)+1) | D18: =INDEX(Scoring!$D:$D,MATCH($H$18,Scoring!$U$2:$U$112,0)+1) | E18: =INDEX(Scoring!$R:$R,MATCH($H$18,Scoring!$U$2:$U$112,0)+1) | F18: =INDEX(Scoring!$J:$J,MATCH($H$18,Scoring!$U$2:$U$112,0)+1) | H18: =LARGE(Scoring!$U$2:$U$112,14)
A19: 15 | B19: =INDEX(Scoring!$B:$B,MATCH($H$19,Scoring!$U$2:$U$112,0)+1) | C19: =INDEX(Scoring!$C:$C,MATCH($H$19,Scoring!$U$2:$U$112,0)+1) | D19: =INDEX(Scoring!$D:$D,MATCH($H$19,Scoring!$U$2:$U$112,0)+1) | E19: =INDEX(Scoring!$R:$R,MATCH($H$19,Scoring!$U$2:$U$112,0)+1) | F19: =INDEX(Scoring!$J:$J,MATCH($H$19,Scoring!$U$2:$U$112,0)+1) | H19: =LARGE(Scoring!$U$2:$U$112,15)
A21: ↑ Live — these rankings recalculate when you edit the User Input sheet.

Sheet Best Overall
A1: Best overall matches — the real recommendation
A2: Ranked by combined score (50% built-for + 50% enjoyment). Sports here are where your body and your preferences agree.
A4: # | B4: Sport | C4: Position / Discipline | D4: Category | E4: TOTAL | F4: Built / Enjoy
A5: 1 | B5: =INDEX(Scoring!$B:$B,MATCH($H$5,Scoring!$V$2:$V$112,0)+1) | C5: =INDEX(Scoring!$C:$C,MATCH($H$5,Scoring!$V$2:$V$112,0)+1) | D5: =INDEX(Scoring!$D:$D,MATCH($H$5,Scoring!$V$2:$V$112,0)+1) | E5: =INDEX(Scoring!$S:$S,MATCH($H$5,Scoring!$V$2:$V$112,0)+1) | F5: =INDEX(Scoring!$J:$J,MATCH($H$5,Scoring!$V$2:$V$112,0)+1)&" / "&INDEX(Scoring!$R:$R,MATCH($H$5,Scoring!$V$2:$V$112,0)+1) | H5: =LARGE(Scoring!$V$2:$V$112,1)
A6: 2 | B6: =INDEX(Scoring!$B:$B,MATCH($H$6,Scoring!$V$2:$V$112,0)+1) | C6: =INDEX(Scoring!$C:$C,MATCH($H$6,Scoring!$V$2:$V$112,0)+1) | D6: =INDEX(Scoring!$D:$D,MATCH($H$6,Scoring!$V$2:$V$112,0)+1) | E6: =INDEX(Scoring!$S:$S,MATCH($H$6,Scoring!$V$2:$V$112,0)+1) | F6: =INDEX(Scoring!$J:$J,MATCH($H$6,Scoring!$V$2:$V$112,0)+1)&" / "&INDEX(Scoring!$R:$R,MATCH($H$6,Scoring!$V$2:$V$112,0)+1) | H6: =LARGE(Scoring!$V$2:$V$112,2)
A7: 3 | B7: =INDEX(Scoring!$B:$B,MATCH($H$7,Scoring!$V$2:$V$112,0)+1) | C7: =INDEX(Scoring!$C:$C,MATCH($H$7,Scoring!$V$2:$V$112,0)+1) | D7: =INDEX(Scoring!$D:$D,MATCH($H$7,Scoring!$V$2:$V$112,0)+1) | E7: =INDEX(Scoring!$S:$S,MATCH($H$7,Scoring!$V$2:$V$112,0)+1) | F7: =INDEX(Scoring!$J:$J,MATCH($H$7,Scoring!$V$2:$V$112,0)+1)&" / "&INDEX(Scoring!$R:$R,MATCH($H$7,Scoring!$V$2:$V$112,0)+1) | H7: =LARGE(Scoring!$V$2:$V$112,3)
A8: 4 | B8: =INDEX(Scoring!$B:$B,MATCH($H$8,Scoring!$V$2:$V$112,0)+1) | C8: =INDEX(Scoring!$C:$C,MATCH($H$8,Scoring!$V$2:$V$112,0)+1) | D8: =INDEX(Scoring!$D:$D,MATCH($H$8,Scoring!$V$2:$V$112,0)+1) | E8: =INDEX(Scoring!$S:$S,MATCH($H$8,Scoring!$V$2:$V$112,0)+1) | F8: =INDEX(Scoring!$J:$J,MATCH($H$8,Scoring!$V$2:$V$112,0)+1)&" / "&INDEX(Scoring!$R:$R,MATCH($H$8,Scoring!$V$2:$V$112,0)+1) | H8: =LARGE(Scoring!$V$2:$V$112,4)
A9: 5 | B9: =INDEX(Scoring!$B:$B,MATCH($H$9,Scoring!$V$2:$V$112,0)+1) | C9: =INDEX(Scoring!$C:$C,MATCH($H$9,Scoring!$V$2:$V$112,0)+1) | D9: =INDEX(Scoring!$D:$D,MATCH($H$9,Scoring!$V$2:$V$112,0)+1) | E9: =INDEX(Scoring!$S:$S,MATCH($H$9,Scoring!$V$2:$V$112,0)+1) | F9: =INDEX(Scoring!$J:$J,MATCH($H$9,Scoring!$V$2:$V$112,0)+1)&" / "&INDEX(Scoring!$R:$R,MATCH($H$9,Scoring!$V$2:$V$112,0)+1) | H9: =LARGE(Scoring!$V$2:$V$112,5)
A10: 6 | B10: =INDEX(Scoring!$B:$B,MATCH($H$10,Scoring!$V$2:$V$112,0)+1) | C10: =INDEX(Scoring!$C:$C,MATCH($H$10,Scoring!$V$2:$V$112,0)+1) | D10: =INDEX(Scoring!$D:$D,MATCH($H$10,Scoring!$V$2:$V$112,0)+1) | E10: =INDEX(Scoring!$S:$S,MATCH($H$10,Scoring!$V$2:$V$112,0)+1) | F10: =INDEX(Scoring!$J:$J,MATCH($H$10,Scoring!$V$2:$V$112,0)+1)&" / "&INDEX(Scoring!$R:$R,MATCH($H$10,Scoring!$V$2:$V$112,0)+1) | H10: =LARGE(Scoring!$V$2:$V$112,6)
A11: 7 | B11: =INDEX(Scoring!$B:$B,MATCH($H$11,Scoring!$V$2:$V$112,0)+1) | C11: =INDEX(Scoring!$C:$C,MATCH($H$11,Scoring!$V$2:$V$112,0)+1) | D11: =INDEX(Scoring!$D:$D,MATCH($H$11,Scoring!$V$2:$V$112,0)+1) | E11: =INDEX(Scoring!$S:$S,MATCH($H$11,Scoring!$V$2:$V$112,0)+1) | F11: =INDEX(Scoring!$J:$J,MATCH($H$11,Scoring!$V$2:$V$112,0)+1)&" / "&INDEX(Scoring!$R:$R,MATCH($H$11,Scoring!$V$2:$V$112,0)+1) | H11: =LARGE(Scoring!$V$2:$V$112,7)
A12: 8 | B12: =INDEX(Scoring!$B:$B,MATCH($H$12,Scoring!$V$2:$V$112,0)+1) | C12: =INDEX(Scoring!$C:$C,MATCH($H$12,Scoring!$V$2:$V$112,0)+1) | D12: =INDEX(Scoring!$D:$D,MATCH($H$12,Scoring!$V$2:$V$112,0)+1) | E12: =INDEX(Scoring!$S:$S,MATCH($H$12,Scoring!$V$2:$V$112,0)+1) | F12: =INDEX(Scoring!$J:$J,MATCH($H$12,Scoring!$V$2:$V$112,0)+1)&" / "&INDEX(Scoring!$R:$R,MATCH($H$12,Scoring!$V$2:$V$112,0)+1) | H12: =LARGE(Scoring!$V$2:$V$112,8)
A13: 9 | B13: =INDEX(Scoring!$B:$B,MATCH($H$13,Scoring!$V$2:$V$112,0)+1) | C13: =INDEX(Scoring!$C:$C,MATCH($H$13,Scoring!$V$2:$V$112,0)+1) | D13: =INDEX(Scoring!$D:$D,MATCH($H$13,Scoring!$V$2:$V$112,0)+1) | E13: =INDEX(Scoring!$S:$S,MATCH($H$13,Scoring!$V$2:$V$112,0)+1) | F13: =INDEX(Scoring!$J:$J,MATCH($H$13,Scoring!$V$2:$V$112,0)+1)&" / "&INDEX(Scoring!$R:$R,MATCH($H$13,Scoring!$V$2:$V$112,0)+1) | H13: =LARGE(Scoring!$V$2:$V$112,9)
A14: 10 | B14: =INDEX(Scoring!$B:$B,MATCH($H$14,Scoring!$V$2:$V$112,0)+1) | C14: =INDEX(Scoring!$C:$C,MATCH($H$14,Scoring!$V$2:$V$112,0)+1) | D14: =INDEX(Scoring!$D:$D,MATCH($H$14,Scoring!$V$2:$V$112,0)+1) | E14: =INDEX(Scoring!$S:$S,MATCH($H$14,Scoring!$V$2:$V$112,0)+1) | F14: =INDEX(Scoring!$J:$J,MATCH($H$14,Scoring!$V$2:$V$112,0)+1)&" / "&INDEX(Scoring!$R:$R,MATCH($H$14,Scoring!$V$2:$V$112,0)+1) | H14: =LARGE(Scoring!$V$2:$V$112,10)
A15: 11 | B15: =INDEX(Scoring!$B:$B,MATCH($H$15,Scoring!$V$2:$V$112,0)+1) | C15: =INDEX(Scoring!$C:$C,MATCH($H$15,Scoring!$V$2:$V$112,0)+1) | D15: =INDEX(Scoring!$D:$D,MATCH($H$15,Scoring!$V$2:$V$112,0)+1) | E15: =INDEX(Scoring!$S:$S,MATCH($H$15,Scoring!$V$2:$V$112,0)+1) | F15: =INDEX(Scoring!$J:$J,MATCH($H$15,Scoring!$V$2:$V$112,0)+1)&" / "&INDEX(Scoring!$R:$R,MATCH($H$15,Scoring!$V$2:$V$112,0)+1) | H15: =LARGE(Scoring!$V$2:$V$112,11)
A16: 12 | B16: =INDEX(Scoring!$B:$B,MATCH($H$16,Scoring!$V$2:$V$112,0)+1) | C16: =INDEX(Scoring!$C:$C,MATCH($H$16,Scoring!$V$2:$V$112,0)+1) | D16: =INDEX(Scoring!$D:$D,MATCH($H$16,Scoring!$V$2:$V$112,0)+1) | E16: =INDEX(Scoring!$S:$S,MATCH($H$16,Scoring!$V$2:$V$112,0)+1) | F16: =INDEX(Scoring!$J:$J,MATCH($H$16,Scoring!$V$2:$V$112,0)+1)&" / "&INDEX(Scoring!$R:$R,MATCH($H$16,Scoring!$V$2:$V$112,0)+1) | H16: =LARGE(Scoring!$V$2:$V$112,12)
A17: 13 | B17: =INDEX(Scoring!$B:$B,MATCH($H$17,Scoring!$V$2:$V$112,0)+1) | C17: =INDEX(Scoring!$C:$C,MATCH($H$17,Scoring!$V$2:$V$112,0)+1) | D17: =INDEX(Scoring!$D:$D,MATCH($H$17,Scoring!$V$2:$V$112,0)+1) | E17: =INDEX(Scoring!$S:$S,MATCH($H$17,Scoring!$V$2:$V$112,0)+1) | F17: =INDEX(Scoring!$J:$J,MATCH($H$17,Scoring!$V$2:$V$112,0)+1)&" / "&INDEX(Scoring!$R:$R,MATCH($H$17,Scoring!$V$2:$V$112,0)+1) | H17: =LARGE(Scoring!$V$2:$V$112,13)
A18: 14 | B18: =INDEX(Scoring!$B:$B,MATCH($H$18,Scoring!$V$2:$V$112,0)+1) | C18: =INDEX(Scoring!$C:$C,MATCH($H$18,Scoring!$V$2:$V$112,0)+1) | D18: =INDEX(Scoring!$D:$D,MATCH($H$18,Scoring!$V$2:$V$112,0)+1) | E18: =INDEX(Scoring!$S:$S,MATCH($H$18,Scoring!$V$2:$V$112,0)+1) | F18: =INDEX(Scoring!$J:$J,MATCH($H$18,Scoring!$V$2:$V$112,0)+1)&" / "&INDEX(Scoring!$R:$R,MATCH($H$18,Scoring!$V$2:$V$112,0)+1) | H18: =LARGE(Scoring!$V$2:$V$112,14)
A19: 15 | B19: =INDEX(Scoring!$B:$B,MATCH($H$19,Scoring!$V$2:$V$112,0)+1) | C19: =INDEX(Scoring!$C:$C,MATCH($H$19,Scoring!$V$2:$V$112,0)+1) | D19: =INDEX(Scoring!$D:$D,MATCH($H$19,Scoring!$V$2:$V$112,0)+1) | E19: =INDEX(Scoring!$S:$S,MATCH($H$19,Scoring!$V$2:$V$112,0)+1) | F19: =INDEX(Scoring!$J:$J,MATCH($H$19,Scoring!$V$2:$V$112,0)+1)&" / "&INDEX(Scoring!$R:$R,MATCH($H$19,Scoring!$V$2:$V$112,0)+1) | H19: =LARGE(Scoring!$V$2:$V$112,15)
A21: ↑ Live — these rankings recalculate when you edit the User Input sheet.

Sheet Scoring
A1: Sport ID | B1: Sport | C1: Position | D1: Category | E1: Height penalty | F1: Weight penalty | G1: BF% penalty | H1: Wingspan penalty | I1: Demand-profile fit (0–100) | J1: Built-for score (0–100) | K1: Sex match | L1: Team/solo match | M1: Contact match | N1: Env match | O1: Water OK | P1: Budget OK | Q1: Ireland fit | R1: Enjoyment score (0–100) | S1: TOTAL (0–100) | T1: _tb_built | U1: _tb_enjoy | V1: _tb_total | W1: Category boost | X1: Experience fit | Y1: Age fit | Z1: Injury fit
A2: =Profiles!A3 | B2: =Profiles!B3 | C2: =Profiles!C3 | D2: =Profiles!D3 | E2: =IF(ISNUMBER(Profiles!E3),IF(ISNUMBER(Profiles!F3),MAX(0,1-(MAX(0,ABS('User Input'!$B$9-Profiles!E3)-Profiles!F3))/Profiles!F3/3),MAX(0,1-ABS('User Input'!$B$9-Profiles!E3)/(Profiles!E3*0.1)/3)),0.5) | F2: =IF(ISNUMBER(Profiles!G3),IF(ISNUMBER(Profiles!H3),MAX(0,1-(MAX(0,ABS('User Input'!$B$10-Profiles!G3)-Profiles!H3))/Profiles!H3/3),MAX(0,1-ABS('User Input'!$B$10-Profiles!G3)/(Profiles!G3*0.15)/3)),0.5) | G2: =IF(ISNUMBER(Profiles!J3),MAX(0,1-ABS('User Input'!$B$12-Profiles!J3)/5/3),0.5) | H2: =IF(ISNUMBER(Profiles!K3),MAX(0,1-ABS('User Input'!$B$14-Profiles!K3)/0.03/3),"n/a") | I2: =100*MAX(0,1-(MAX(0,Profiles!M3-'User Input'!$B$17)+0.5*MAX(0,'User Input'!$B$17-Profiles!M3)+MAX(0,Profiles!N3-'User Input'!$B$18)+0.5*MAX(0,'User Input'!$B$18-Profiles!N3)+MAX(0,Profiles!O3-'User Input'!$B$19)+0.5*MAX(0,'User Input'!$B$19-Profiles!O3)+MAX(0,Profiles!P3-'User Input'!$B$20)+0.5*MAX(0,'User Input'!$B$20-Profiles!P3)+MAX(0,Profiles!Q3-'User Input'!$B$21)+0.5*MAX(0,'User Input'!$B$21-Profiles!Q3)+MAX(0,Profiles!S3-'User Input'!$B$22)+0.5*MAX(0,'User Input'!$B$22-Profiles!S3)+MAX(0,Profiles!T3-'User Input'!$B$23)+0.5*MAX(0,'User Input'!$B$23-Profiles!T3)+MAX(0,Profiles!U3-'User Input'!$B$24)+0.5*MAX(0,'User Input'!$B$24-Profiles!U3))/40) | J2: =ROUND(60*(E2+F2+G2+IFERROR(VALUE(H2),(E2+F2+G2)/3))/4 + 0.4*I2,1) | K2: =IF(OR(AND('User Input'!$B$6="M",Profiles!$AG3="M"),AND('User Input'!$B$6="F",Profiles!$AG3="F")),1,0) | L2: =IF('User Input'!$B$27="Either",(IF(Profiles!V3>=4,1,0.3)+IF(OR(Profiles!V3<=2,ISNUMBER(SEARCH("Individual",Profiles!D3))),1,0.3))/2,IF('User Input'!$B$27="Team",IF(Profiles!V3>=4,1,0.3),IF(OR(Profiles!V3<=2,ISNUMBER(SEARCH("Individual",Profiles!D3))),1,0.3))) | M2: =IF(IFERROR(MATCH(Profiles!W3,{"None","Light","Medium","Heavy"},0)-1,0)<=IFERROR(MATCH('User Input'!$B$28,{"None","Light","Medium","Heavy"},0)-1,3),1,MAX(0,1-0.4*(IFERROR(MATCH(Profiles!W3,{"None","Light","Medium","Heavy"},0)-1,0)-IFERROR(MATCH('User Input'!$B$28,{"None","Light","Medium","Heavy"},0)-1,3)))) | N2: =IF('User Input'!$B$29="neutral",1,IF('User Input'!$B$29="essential",IF(ISNUMBER(SEARCH("Outdoor",Profiles!X3)),1,0.3),IF('User Input'!$B$29="nice",IF(ISNUMBER(SEARCH("Outdoor",Profiles!X3)),1,0.65),IF('User Input'!$B$29="indoor",IF(ISNUMBER(SEARCH("Indoor",Profiles!X3)),1,0.4),1)))) | O2: =IF('User Input'!$B$30="Yes",1,IF(Profiles!Y3="Yes",0,1)) | P2: =IF(IFERROR(MATCH(Profiles!Z3,{"Low","Medium","High"},0),2)<=IFERROR(MATCH('User Input'!$B$31,{"Low","Medium","High"},0),2),1,MAX(0,1-0.4*(IFERROR(MATCH(Profiles!Z3,{"Low","Medium","High"},0),2)-IFERROR(MATCH('User Input'!$B$31,{"Low","Medium","High"},0),2)))) | Q2: =IF('User Input'!$B$32="Yes",IF(ISNUMBER(Profiles!AC3),Profiles!AC3/10,0.5),1) | R2: =IF(OR(K2=0,O2=0),0,ROUND(MIN(100,100*(K2*0.1+L2*0.2+M2*0.2+N2*0.1+P2*0.15+Q2*0.25)*W2*X2*Y2*Z2),1)) | S2: =IF(R2=0,0,ROUND(0.5*J2+0.5*R2,1)) | T2: =J2-ROW()/1000000 | U2: =R2-ROW()/1000000 | V2: =S2-ROW()/1000000 | W2: =IF(OR(AND(OR(Profiles!D3="Team field",Profiles!D3="Team field contact",Profiles!D3="Team field stick"),'User Input'!$B$34="Yes"),AND(OR(Profiles!D3="Team court",Profiles!D3="Team court contact"),'User Input'!$B$35="Yes"),AND(Profiles!D3="Individual racquet",'User Input'!$B$36="Yes"),AND(OR(Profiles!D3="Combat striking",Profiles!D3="Combat grappling",Profiles!D3="Combat mixed"),'User Input'!$B$37="Yes"),AND(OR(Profiles!D3="Team water contact",Profiles!D3="Individual water"),'User Input'!$B$38="Yes"),AND(OR(Profiles!D3="Endurance individual",Profiles!D3="Endurance individual / pair",Profiles!D3="Endurance individual / pursuit",Profiles!D3="Endurance team / pair",Profiles!D3="Endurance multi"),'User Input'!$B$39="Yes"),AND(OR(Profiles!D3="Strength individual",Profiles!D3="Power-throw individual"),'User Input'!$B$40="Yes"),AND(OR(Profiles!D3="Individual technical",Profiles!D3="Individual aesthetic",Profiles!D3="Team precision"),'User Input'!$B$41="Yes")),1.15,1) | X2: =IF('User Input'!$B$33<>"none",1,IF(IFERROR(VALUE(TRIM(MID(SUBSTITUTE(SUBSTITUTE(Profiles!AA3,"–","-"),"-",REPT(" ",100)),100,100)))<=14,FALSE),0.7,1)) | Y2: =IF(OR('User Input'!$B$42="under30",'User Input'!$B$42=""),1,IF('User Input'!$B$42="30to45",IF((IFERROR(MATCH(Profiles!W3,{"None","Light","Medium","Heavy"},0)-1,0)+IFERROR(MATCH(Profiles!AB3,{"Low","Medium","High"},0)-1,0))>=5,0.85,1),IF('User Input'!$B$42="46to60",IF((IFERROR(MATCH(Profiles!W3,{"None","Light","Medium","Heavy"},0)-1,0)+IFERROR(MATCH(Profiles!AB3,{"Low","Medium","High"},0)-1,0))>=5,0.65,IF((IFERROR(MATCH(Profiles!W3,{"None","Light","Medium","Heavy"},0)-1,0)+IFERROR(MATCH(Profiles!AB3,{"Low","Medium","High"},0)-1,0))>=4,0.8,IF((IFERROR(MATCH(Profiles!W3,{"None","Light","Medium","Heavy"},0)-1,0)+IFERROR(MATCH(Profiles!AB3,{"Low","Medium","High"},0)-1,0))>=3,0.9,1))),IF((IFERROR(MATCH(Profiles!W3,{"None","Light","Medium","Heavy"},0)-1,0)+IFERROR(MATCH(Profiles!AB3,{"Low","Medium","High"},0)-1,0))>=5,0.4,IF((IFERROR(MATCH(Profiles!W3,{"None","Light","Medium","Heavy"},0)-1,0)+IFERROR(MATCH(Profiles!AB3,{"Low","Medium","High"},0)-1,0))>=4,0.6,IF((IFERROR(MATCH(Profiles!W3,{"None","Light","Medium","Heavy"},0)-1,0)+IFERROR(MATCH(Profiles!AB3,{"Low","Medium","High"},0)-1,0))>=3,0.75,IF((IFERROR(MATCH(Profiles!W3,{"None","Light","Medium","Heavy"},0)-1,0)+IFERROR(MATCH(Profiles!AB3,{"Low","Medium","High"},0)-1,0))>=2,0.85,1))))))) | Z2: =IF(OR('User Input'!$B$43="none",'User Input'!$B$43=""),1,IF('User Input'!$B$43="minor",IF(IFERROR(MATCH(Profiles!W3,{"None","Light","Medium","Heavy"},0)-1,0)>=3,0.7,IF(IFERROR(MATCH(Profiles!W3,{"None","Light","Medium","Heavy"},0)-1,0)>=2,0.85,1)),IF('User Input'!$B$43="joint",IF(OR(IFERROR(MATCH(Profiles!W3,{"None","Light","Medium","Heavy"},0)-1,0)>=3,IFERROR(MATCH(Profiles!AB3,{"Low","Medium","High"},0)-1,0)>=2),0.5,IF(OR(IFERROR(MATCH(Profiles!W3,{"None","Light","Medium","Heavy"},0)-1,0)>=2,IFERROR(MATCH(Profiles!AB3,{"Low","Medium","High"},0)-1,0)>=1),0.75,1)),IF(OR(IFERROR(MATCH(Profiles!W3,{"None","Light","Medium","Heavy"},0)-1,0)>=2,IFERROR(MATCH(Profiles!AB3,{"Low","Medium","High"},0)-1,0)>=2),0.3,IF(OR(IFERROR(MATCH(Profiles!W3,{"None","Light","Medium","Heavy"},0)-1,0)>=1,IFERROR(MATCH(Profiles!AB3,{"Low","Medium","High"},0)-1,0)>=1),0.6,0.9)))))
A3: =Profiles!A4 | B3: =Profiles!B4 | C3: =Profiles!C4 | D3: =Profiles!D4 | E3: =IF(ISNUMBER(Profiles!E4),IF(ISNUMBER(Profiles!F4),MAX(0,1-(MAX(0,ABS('User Input'!$B$9-Profiles!E4)-Profiles!F4))/Profiles!F4/3),MAX(0,1-ABS('User Input'!$B$9-Profiles!E4)/(Profiles!E4*0.1)/3)),0.5) | F3: =IF(ISNUMBER(Profiles!G4),IF(ISNUMBER(Profiles!H4),MAX(0,1-(MAX(0,ABS('User Input'!$B$10-Profiles!G4)-Profiles!H4))/Profiles!H4/3),MAX(0,1-ABS('User Input'!$B$10-Profiles!G4)/(Profiles!G4*0.15)/3)),0.5) | G3: =IF(ISNUMBER(Profiles!J4),MAX(0,1-ABS('User Input'!$B$12-Profiles!J4)/5/3),0.5) | H3: =IF(ISNUMBER(Profiles!K4),MAX(0,1-ABS('User Input'!$B$14-Profiles!K4)/0.03/3),"n/a") | I3: =100*MAX(0,1-(MAX(0,Profiles!M4-'User Input'!$B$17)+0.5*MAX(0,'User Input'!$B$17-Profiles!M4)+MAX(0,Profiles!N4-'User Input'!$B$18)+0.5*MAX(0,'User Input'!$B$18-Profiles!N4)+MAX(0,Profiles!O4-'User Input'!$B$19)+0.5*MAX(0,'User Input'!$B$19-Profiles!O4)+MAX(0,Profiles!P4-'User Input'!$B$20)+0.5*MAX(0,'User Input'!$B$20-Profiles!P4)+MAX(0,Profiles!Q4-'User Input'!$B$21)+0.5*MAX(0,'User Input'!$B$21-Profiles!Q4)+MAX(0,Profiles!S4-'User Input'!$B$22)+0.5*MAX(0,'User Input'!$B$22-Profiles!S4)+MAX(0,Profiles!T4-'User Input'!$B$23)+0.5*MAX(0,'User Input'!$B$23-Profiles!T4)+MAX(0,Profiles!U4-'User Input'!$B$24)+0.5*MAX(0,'User Input'!$B$24-Profiles!U4))/40) | J3: =ROUND(60*(E3+F3+G3+IFERROR(VALUE(H3),(E3+F3+G3)/3))/4 + 0.4*I3,1) | K3: =IF(OR(AND('User Input'!$B$6="M",Profiles!$AG4="M"),AND('User Input'!$B$6="F",Profiles!$AG4="F")),1,0) | L3: =IF('User Input'!$B$27="Either",(IF(Profiles!V4>=4,1,0.3)+IF(OR(Profiles!V4<=2,ISNUMBER(SEARCH("Individual",Profiles!D4))),1,0.3))/2,IF('User Input'!$B$27="Team",IF(Profiles!V4>=4,1,0.3),IF(OR(Profiles!V4<=2,ISNUMBER(SEARCH("Individual",Profiles!D4))),1,0.3))) | M3: =IF(IFERROR(MATCH(Profiles!W4,{"None","Light","Medium","Heavy"},0)-1,0)<=IFERROR(MATCH('User Input'!$B$28,{"None","Light","Medium","Heavy"},0)-1,3),1,MAX(0,1-0.4*(IFERROR(MATCH(Profiles!W4,{"None","Light","Medium","Heavy"},0)-1,0)-IFERROR(MATCH('User Input'!$B$28,{"None","Light","Medium","Heavy"},0)-1,3)))) | N3: =IF('User Input'!$B$29="neutral",1,IF('User Input'!$B$29="essential",IF(ISNUMBER(SEARCH("Outdoor",Profiles!X4)),1,0.3),IF('User Input'!$B$29="nice",IF(ISNUMBER(SEARCH("Outdoor",Profiles!X4)),1,0.65),IF('User Input'!$B$29="indoor",IF(ISNUMBER(SEARCH("Indoor",Profiles!X4)),1,0.4),1)))) | O3: =IF('User Input'!$B$30="Yes",1,IF(Profiles!Y4="Yes",0,1)) | P3: =IF(IFERROR(MATCH(Profiles!Z4,{"Low","Medium","High"},0),2)<=IFERROR(MATCH('User Input'!$B$31,{"Low","Medium","High"},0),2),1,MAX(0,1-0.4*(IFERROR(MATCH(Profiles!Z4,{"Low","Medium","High"},0),2)-IFERROR(MATCH('User Input'!$B$31,{"Low","Medium","High"},0),2)))) | Q3: =IF('User Input'!$B$32="Yes",IF(ISNUMBER(Profiles!AC4),Profiles!AC4/10,0.5),1) | R3: =IF(OR(K3=0,O3=0),0,ROUND(MIN(100,100*(K3*0.1+L3*0.2+M3*0.2+N3*0.1+P3*0.15+Q3*0.25)*W3*X3*Y3*Z3),1)) | S3: =IF(R3=0,0,ROUND(0.5*J3+0.5*R3,1)) | T3: =J3-ROW()/1000000 | U3: =R3-ROW()/1000000 | V3: =S3-ROW()/1000000 | W3: =IF(OR(AND(OR(Profiles!D4="Team field",Profiles!D4="Team field contact",Profiles!D4="Team field stick"),'User Input'!$B$34="Yes"),AND(OR(Profiles!D4="Team court",Profiles!D4="Team court contact"),'User Input'!$B$35="Yes"),AND(Profiles!D4="Individual racquet",'User Input'!$B$36="Yes"),AND(OR(Profiles!D4="Combat striking",Profiles!D4="Combat grappling",Profiles!D4="Combat mixed"),'User Input'!$B$37="Yes"),AND(OR(Profiles!D4="Team water contact",Profiles!D4="Individual water"),'User Input'!$B$38="Yes"),AND(OR(Profiles!D4="Endurance individual",Profiles!D4="Endurance individual / pair",Profiles!D4="Endurance individual / pursuit",Profiles!D4="Endurance team / pair",Profiles!D4="Endurance multi"),'User Input'!$B$39="Yes"),AND(OR(Profiles!D4="Strength individual",Profiles!D4="Power-throw individual"),'User Input'!$B$40="Yes"),AND(OR(Profiles!D4="Individual technical",Profiles!D4="Individual aesthetic",Profiles!D4="Team precision"),'User Input'!$B$41="Yes")),1.15,1) | X3: =IF('User Input'!$B$33<>"none",1,IF(IFERROR(VALUE(TRIM(MID(SUBSTITUTE(SUBSTITUTE(Profiles!AA4,"–","-"),"-",REPT(" ",100)),100,100)))<=14,FALSE),0.7,1)) | Y3: =IF(OR('User Input'!$B$42="under30",'User Input'!$B$42=""),1,IF('User Input'!$B$42="30to45",IF((IFERROR(MATCH(Profiles!W4,{"None","Light","Medium","Heavy"},0)-1,0)+IFERROR(MATCH(Profiles!AB4,{"Low","Medium","High"},0)-1,0))>=5,0.85,1),IF('User Input'!$B$42="46to60",IF((IFERROR(MATCH(Profiles!W4,{"None","Light","Medium","Heavy"},0)-1,0)+IFERROR(MATCH(Profiles!AB4,{"Low","Medium","High"},0)-1,0))>=5,0.65,IF((IFERROR(MATCH(Profiles!W4,{"None","Light","Medium","Heavy"},0)-1,0)+IFERROR(MATCH(Profiles!AB4,{"Low","Medium","High"},0)-1,0))>=4,0.8,IF((IFERROR(MATCH(Profiles!W4,{"None","Light","Medium","Heavy"},0)-1,0)+IFERROR(MATCH(Profiles!AB4,{"Low","Medium","High"},0)-1,0))>=3,0.9,1))),IF((IFERROR(MATCH(Profiles!W4,{"None","Light","Medium","Heavy"},0)-1,0)+IFERROR(MATCH(Profiles!AB4,{"Low","Medium","High"},0)-1,0))>=5,0.4,IF((IFERROR(MATCH(Profiles!W4,{"None","Light","Medium","Heavy"},0)-1,0)+IFERROR(MATCH(Profiles!AB4,{"Low","Medium","High"},0)-1,0))>=4,0.6,IF((IFERROR(MATCH(Profiles!W4,{"None","Light","Medium","Heavy"},0)-1,0)+IFERROR(MATCH(Profiles!AB4,{"Low","Medium","High"},0)-1,0))>=3,0.75,IF((IFERROR(MATCH(Profiles!W4,{"None","Light","Medium","Heavy"},0)-1,0)+IFERROR(MATCH(Profiles!AB4,{"Low","Medium","High"},0)-1,0))>=2,0.85,1))))))) | Z3: =IF(OR('User Input'!$B$43="none",'User Input'!$B$43=""),1,IF('User Input'!$B$43="minor",IF(IFERROR(MATCH(Profiles!W4,{"None","Light","Medium","Heavy"},0)-1,0)>=3,0.7,IF(IFERROR(MATCH(Profiles!W4,{"None","Light","Medium","Heavy"},0)-1,0)>=2,0.85,1)),IF('User Input'!$B$43="joint",IF(OR(IFERROR(MATCH(Profiles!W4,{"None","Light","Medium","Heavy"},0)-1,0)>=3,IFERROR(MATCH(Profiles!AB4,{"Low","Medium","High"},0)-1,0)>=2),0.5,IF(OR(IFERROR(MATCH(Profiles!W4,{"None","Light","Medium","Heavy"},0)-1,0)>=2,IFERROR(MATCH(Profiles!AB4,{"Low","Medium","High"},0)-1,0)>=1),0.75,1)),IF(OR(IFERROR(MATCH(Profiles!W4,{"None","Light","Medium","Heavy"},0)-1,0)>=2,IFERROR(MATCH(Profiles!AB4,{"Low","Medium","High"},0)-1,0)>=2),0.3,IF(OR(IFERROR(MATCH(Profiles!W4,{"None","Light","Medium","Heavy"},0)-1,0)>=1,IFERROR(MATCH(Profiles!AB4,{"Low","Medium","High"},0)-1,0)>=1),0.6,0.9)))))
A4: =Profiles!A5 | B4: =Profiles!B5 | C4: =Profiles!C5 | D4: =Profiles!D5 | E4: =IF(ISNUMBER(Profiles!E5),IF(ISNUMBER(Profiles!F5),MAX(0,1-(MAX(0,ABS('User Input'!$B$9-Profiles!E5)-Profiles!F5))/Profiles!F5/3),MAX(0,1-ABS('User Input'!$B$9-Profiles!E5)/(Profiles!E5*0.1)/3)),0.5) | F4: =IF(ISNUMBER(Profiles!G5),IF(ISNUMBER(Profiles!H5),MAX(0,1-(MAX(0,ABS('User Input'!$B$10-Profiles!G5)-Profiles!H5))/Profiles!H5/3),MAX(0,1-ABS('User Input'!$B$10-Profiles!G5)/(Profiles!G5*0.15)/3)),0.5) | G4: =IF(ISNUMBER(Profiles!J5),MAX(0,1-ABS('User Input'!$B$12-Profiles!J5)/5/3),0.5) | H4: =IF(ISNUMBER(Profiles!K5),MAX(0,1-ABS('User Input'!$B$14-Profiles!K5)/0.03/3),"n/a") | I4: =100*MAX(0,1-(MAX(0,Profiles!M5-'User Input'!$B$17)+0.5*MAX(0,'User Input'!$B$17-Profiles!M5)+MAX(0,Profiles!N5-'User Input'!$B$18)+0.5*MAX(0,'User Input'!$B$18-Profiles!N5)+MAX(0,Profiles!O5-'User Input'!$B$19)+0.5*MAX(0,'User Input'!$B$19-Profiles!O5)+MAX(0,Profiles!P5-'User Input'!$B$20)+0.5*MAX(0,'User Input'!$B$20-Profiles!P5)+MAX(0,Profiles!Q5-'User Input'!$B$21)+0.5*MAX(0,'User Input'!$B$21-Profiles!Q5)+MAX(0,Profiles!S5-'User Input'!$B$22)+0.5*MAX(0,'User Input'!$B$22-Profiles!S5)+MAX(0,Profiles!T5-'User Input'!$B$23)+0.5*MAX(0,'User Input'!$B$23-Profiles!T5)+MAX(0,Profiles!U5-'User Input'!$B$24)+0.5*MAX(0,'User Input'!$B$24-Profiles!U5))/40) | J4: =ROUND(60*(E4+F4+G4+IFERROR(VALUE(H4),(E4+F4+G4)/3))/4 + 0.4*I4,1) | K4: =IF(OR(AND('User Input'!$B$6="M",Profiles!$AG5="M"),AND('User Input'!$B$6="F",Profiles!$AG5="F")),1,0) | L4: =IF('User Input'!$B$27="Either",(IF(Profiles!V5>=4,1,0.3)+IF(OR(Profiles!V5<=2,ISNUMBER(SEARCH("Individual",Profiles!D5))),1,0.3))/2,IF('User Input'!$B$27="Team",IF(Profiles!V5>=4,1,0.3),IF(OR(Profiles!V5<=2,ISNUMBER(SEARCH("Individual",Profiles!D5))),1,0.3))) | M4: =IF(IFERROR(MATCH(Profiles!W5,{"None","Light","Medium","Heavy"},0)-1,0)<=IFERROR(MATCH('User Input'!$B$28,{"None","Light","Medium","Heavy"},0)-1,3),1,MAX(0,1-0.4*(IFERROR(MATCH(Profiles!W5,{"None","Light","Medium","Heavy"},0)-1,0)-IFERROR(MATCH('User Input'!$B$28,{"None","Light","Medium","Heavy"},0)-1,3)))) | N4: =IF('User Input'!$B$29="neutral",1,IF('User Input'!$B$29="essential",IF(ISNUMBER(SEARCH("Outdoor",Profiles!X5)),1,0.3),IF('User Input'!$B$29="nice",IF(ISNUMBER(SEARCH("Outdoor",Profiles!X5)),1,0.65),IF('User Input'!$B$29="indoor",IF(ISNUMBER(SEARCH("Indoor",Profiles!X5)),1,0.4),1)))) | O4: =IF('User Input'!$B$30="Yes",1,IF(Profiles!Y5="Yes",0,1)) | P4: =IF(IFERROR(MATCH(Profiles!Z5,{"Low","Medium","High"},0),2)<=IFERROR(MATCH('User Input'!$B$31,{"Low","Medium","High"},0),2),1,MAX(0,1-0.4*(IFERROR(MATCH(Profiles!Z5,{"Low","Medium","High"},0),2)-IFERROR(MATCH('User Input'!$B$31,{"Low","Medium","High"},0),2)))) | Q4: =IF('User Input'!$B$32="Yes",IF(ISNUMBER(Profiles!AC5),Profiles!AC5/10,0.5),1) | R4: =IF(OR(K4=0,O4=0),0,ROUND(MIN(100,100*(K4*0.1+L4*0.2+M4*0.2+N4*0.1+P4*0.15+Q4*0.25)*W4*X4*Y4*Z4),1)) | S4: =IF(R4=0,0,ROUND(0.5*J4+0.5*R4,1)) | T4: =J4-ROW()/1000000 | U4: =R4-ROW()/1000000 | V4: =S4-ROW()/1000000 | W4: =IF(OR(AND(OR(Profiles!D5="Team field",Profiles!D5="Team field contact",Profiles!D5="Team field stick"),'User Input'!$B$34="Yes"),AND(OR(Profiles!D5="Team court",Profiles!D5="Team court contact"),'User Input'!$B$35="Yes"),AND(Profiles!D5="Individual racquet",'User Input'!$B$36="Yes"),AND(OR(Profiles!D5="Combat striking",Profiles!D5="Combat grappling",Profiles!D5="Combat mixed"),'User Input'!$B$37="Yes"),AND(OR(Profiles!D5="Team water contact",Profiles!D5="Individual water"),'User Input'!$B$38="Yes"),AND(OR(Profiles!D5="Endurance individual",Profiles!D5="Endurance individual / pair",Profiles!D5="Endurance individual / pursuit",Profiles!D5="Endurance team / pair",Profiles!D5="Endurance multi"),'User Input'!$B$39="Yes"),AND(OR(Profiles!D5="Strength individual",Profiles!D5="Power-throw individual"),'User Input'!$B$40="Yes"),AND(OR(Profiles!D5="Individual technical",Profiles!D5="Individual aesthetic",Profiles!D5="Team precision"),'User Input'!$B$41="Yes")),1.15,1) | X4: =IF('User Input'!$B$33<>"none",1,IF(IFERROR(VALUE(TRIM(MID(SUBSTITUTE(SUBSTITUTE(Profiles!AA5,"–","-"),"-",REPT(" ",100)),100,100)))<=14,FALSE),0.7,1)) | Y4: =IF(OR('User Input'!$B$42="under30",'User Input'!$B$42=""),1,IF('User Input'!$B$42="30to45",IF((IFERROR(MATCH(Profiles!W5,{"None","Light","Medium","Heavy"},0)-1,0)+IFERROR(MATCH(Profiles!AB5,{"Low","Medium","High"},0)-1,0))>=5,0.85,1),IF('User Input'!$B$42="46to60",IF((IFERROR(MATCH(Profiles!W5,{"None","Light","Medium","Heavy"},0)-1,0)+IFERROR(MATCH(Profiles!AB5,{"Low","Medium","High"},0)-1,0))>=5,0.65,IF((IFERROR(MATCH(Profiles!W5,{"None","Light","Medium","Heavy"},0)-1,0)+IFERROR(MATCH(Profiles!AB5,{"Low","Medium","High"},0)-1,0))>=4,0.8,IF((IFERROR(MATCH(Profiles!W5,{"None","Light","Medium","Heavy"},0)-1,0)+IFERROR(MATCH(Profiles!AB5,{"Low","Medium","High"},0)-1,0))>=3,0.9,1))),IF((IFERROR(MATCH(Profiles!W5,{"None","Light","Medium","Heavy"},0)-1,0)+IFERROR(MATCH(Profiles!AB5,{"Low","Medium","High"},0)-1,0))>=5,0.4,IF((IFERROR(MATCH(Profiles!W5,{"None","Light","Medium","Heavy"},0)-1,0)+IFERROR(MATCH(Profiles!AB5,{"Low","Medium","High"},0)-1,0))>=4,0.6,IF((IFERROR(MATCH(Profiles!W5,{"None","Light","Medium","Heavy"},0)-1,0)+IFERROR(MATCH(Profiles!AB5,{"Low","Medium","High"},0)-1,0))>=3,0.75,IF((IFERROR(MATCH(Profiles!W5,{"None","Light","Medium","Heavy"},0)-1,0)+IFERROR(MATCH(Profiles!AB5,{"Low","Medium","High"},0)-1,0))>=2,0.85,1))))))) | Z4: =IF(OR('User Input'!$B$43="none",'User Input'!$B$43=""),1,IF('User Input'!$B$43="minor",IF(IFERROR(MATCH(Profiles!W5,{"None","Light","Medium","Heavy"},0)-1,0)>=3,0.7,IF(IFERROR(MATCH(Profiles!W5,{"None","Light","Medium","Heavy"},0)-1,0)>=2,0.85,1)),IF('User Input'!$B$43="joint",IF(OR(IFERROR(MATCH(Profiles!W5,{"None","Light","Medium","Heavy"},0)-1,0)>=3,IFERROR(MATCH(Profiles!AB5,{"Low","Medium","High"},0)-1,0)>=2),0.5,IF(OR(IFERROR(MATCH(Profiles!W5,{"None","Light","Medium","Heavy"},0)-1,0)>=2,IFERROR(MATCH(Profiles!AB5,{"Low","Medium","High"},0)-1,0)>=1),0.75,1)),IF(OR(IFERROR(MATCH(Profiles!W5,{"None","Light","Medium","Heavy"},0)-1,0)>=2,IFERROR(MATCH(Profiles!AB5,{"Low","Medium","High"},0)-1,0)>=2),0.3,IF(OR(IFERROR(MATCH(Profiles!W5,{"None","Light","Medium","Heavy"},0)-1,0)>=1,IFERROR(MATCH(Profiles!AB5,{"Low","Medium","High"},0)-1,0)>=1),0.6,0.9)))))
A5: =Profiles!A6 | B5: =Profiles!B6 | C5: =Profiles!C6 | D5: =Profiles!D6 | E5: =IF(ISNUMBER(Profiles!E6),IF(ISNUMBER(Profiles!F6),MAX(0,1-(MAX(0,ABS('User Input'!$B$9-Profiles!E6)-Profiles!F6))/Profiles!F6/3),MAX(0,1-ABS('User Input'!$B$9-Profiles!E6)/(Profiles!E6*0.1)/3)),0.5) | F5: =IF(ISNUMBER(Profiles!G6),IF(ISNUMBER(Profiles!H6),MAX(0,1-(MAX(0,ABS('User Input'!$B$10-Profiles!G6)-Profiles!H6))/Profiles!H6/3),MAX(0,1-ABS('User Input'!$B$10-Profiles!G6)/(Profiles!G6*0.15)/3)),0.5) | G5: =IF(ISNUMBER(Profiles!J6),MAX(0,1-ABS('User Input'!$B$12-Profiles!J6)/5/3),0.5) | H5: =IF(ISNUMBER(Profiles!K6),MAX(0,1-ABS('User Input'!$B$14-Profiles!K6)/0.03/3),"n/a") | I5: =100*MAX(0,1-(MAX(0,Profiles!M6-'User Input'!$B$17)+0.5*MAX(0,'User Input'!$B$17-Profiles!M6)+MAX(0,Profiles!N6-'User Input'!$B$18)+0.5*MAX(0,'User Input'!$B$18-Profiles!N6)+MAX(0,Profiles!O6-'User Input'!$B$19)+0.5*MAX(0,'User Input'!$B$19-Profiles!O6)+MAX(0,Profiles!P6-'User Input'!$B$20)+0.5*MAX(0,'User Input'!$B$20-Profiles!P6)+MAX(0,Profiles!Q6-'User Input'!$B$21)+0.5*MAX(0,'User Input'!$B$21-Profiles!Q6)+MAX(0,Profiles!S6-'User Input'!$B$22)+0.5*MAX(0,'User Input'!$B$22-Profiles!S6)+MAX(0,Profiles!T6-'User Input'!$B$23)+0.5*MAX(0,'User Input'!$B$23-Profiles!T6)+MAX(0,Profiles!U6-'User Input'!$B$24)+0.5*MAX(0,'User Input'!$B$24-Profiles!U6))/40) | J5: =ROUND(60*(E5+F5+G5+IFERROR(VALUE(H5),(E5+F5+G5)/3))/4 + 0.4*I5,1) | K5: =IF(OR(AND('User Input'!$B$6="M",Profiles!$AG6="M"),AND('User Input'!$B$6="F",Profiles!$AG6="F")),1,0) | L5: =IF('User Input'!$B$27="Either",(IF(Profiles!V6>=4,1,0.3)+IF(OR(Profiles!V6<=2,ISNUMBER(SEARCH("Individual",Profiles!D6))),1,0.3))/2,IF('User Input'!$B$27="Team",IF(Profiles!V6>=4,1,0.3),IF(OR(Profiles!V6<=2,ISNUMBER(SEARCH("Individual",Profiles!D6))),1,0.3))) | M5: =IF(IFERROR(MATCH(Profiles!W6,{"None","Light","Medium","Heavy"},0)-1,0)<=IFERROR(MATCH('User Input'!$B$28,{"None","Light","Medium","Heavy"},0)-1,3),1,MAX(0,1-0.4*(IFERROR(MATCH(Profiles!W6,{"None","Light","Medium","Heavy"},0)-1,0)-IFERROR(MATCH('User Input'!$B$28,{"None","Light","Medium","Heavy"},0)-1,3)))) | N5: =IF('User Input'!$B$29="neutral",1,IF('User Input'!$B$29="essential",IF(ISNUMBER(SEARCH("Outdoor",Profiles!X6)),1,0.3),IF('User Input'!$B$29="nice",IF(ISNUMBER(SEARCH("Outdoor",Profiles!X6)),1,0.65),IF('User Input'!$B$29="indoor",IF(ISNUMBER(SEARCH("Indoor",Profiles!X6)),1,0.4),1)))) | O5: =IF('User Input'!$B$30="Yes",1,IF(Profiles!Y6="Yes",0,1)) | P5: =IF(IFERROR(MATCH(Profiles!Z6,{"Low","Medium","High"},0),2)<=IFERROR(MATCH('User Input'!$B$31,{"Low","Medium","High"},0),2),1,MAX(0,1-0.4*(IFERROR(MATCH(Profiles!Z6,{"Low","Medium","High"},0),2)-IFERROR(MATCH('User Input'!$B$31,{"Low","Medium","High"},0),2)))) | Q5: =IF('User Input'!$B$32="Yes",IF(ISNUMBER(Profiles!AC6),Profiles!AC6/10,0.5),1) | R5: =IF(OR(K5=0,O5=0),0,ROUND(MIN(100,100*(K5*0.1+L5*0.2+M5*0.2+N5*0.1+P5*0.15+Q5*0.25)*W5*X5*Y5*Z5),1)) | S5: =IF(R5=0,0,ROUND(0.5*J5+0.5*R5,1)) | T5: =J5-ROW()/1000000 | U5: =R5-ROW()/1000000 | V5: =S5-ROW()/1000000 | W5: =IF(OR(AND(OR(Profiles!D6="Team field",Profiles!D6="Team field contact",Profiles!D6="Team field stick"),'User Input'!$B$34="Yes"),AND(OR(Profiles!D6="Team court",Profiles!D6="Team court contact"),'User Input'!$B$35="Yes"),AND(Profiles!D6="Individual racquet",'User Input'!$B$36="Yes"),AND(OR(Profiles!D6="Combat striking",Profiles!D6="Combat grappling",Profiles!D6="Combat mixed"),'User Input'!$B$37="Yes"),AND(OR(Profiles!D6="Team water contact",Profiles!D6="Individual water"),'User Input'!$B$38="Yes"),AND(OR(Profiles!D6="Endurance individual",Profiles!D6="Endurance individual / pair",Profiles!D6="Endurance individual / pursuit",Profiles!D6="Endurance team / pair",Profiles!D6="Endurance multi"),'User Input'!$B$39="Yes"),AND(OR(Profiles!D6="Strength individual",Profiles!D6="Power-throw individual"),'User Input'!$B$40="Yes"),AND(OR(Profiles!D6="Individual technical",Profiles!D6="Individual aesthetic",Profiles!D6="Team precision"),'User Input'!$B$41="Yes")),1.15,1) | X5: =IF('User Input'!$B$33<>"none",1,IF(IFERROR(VALUE(TRIM(MID(SUBSTITUTE(SUBSTITUTE(Profiles!AA6,"–","-"),"-",REPT(" ",100)),100,100)))<=14,FALSE),0.7,1)) | Y5: =IF(OR('User Input'!$B$42="under30",'User Input'!$B$42=""),1,IF('User Input'!$B$42="30to45",IF((IFERROR(MATCH(Profiles!W6,{"None","Light","Medium","Heavy"},0)-1,0)+IFERROR(MATCH(Profiles!AB6,{"Low","Medium","High"},0)-1,0))>=5,0.85,1),IF('User Input'!$B$42="46to60",IF((IFERROR(MATCH(Profiles!W6,{"None","Light","Medium","Heavy"},0)-1,0)+IFERROR(MATCH(Profiles!AB6,{"Low","Medium","High"},0)-1,0))>=5,0.65,IF((IFERROR(MATCH(Profiles!W6,{"None","Light","Medium","Heavy"},0)-1,0)+IFERROR(MATCH(Profiles!AB6,{"Low","Medium","High"},0)-1,0))>=4,0.8,IF((IFERROR(MATCH(Profiles!W6,{"None","Light","Medium","Heavy"},0)-1,0)+IFERROR(MATCH(Profiles!AB6,{"Low","Medium","High"},0)-1,0))>=3,0.9,1))),IF((IFERROR(MATCH(Profiles!W6,{"None","Light","Medium","Heavy"},0)-1,0)+IFERROR(MATCH(Profiles!AB6,{"Low","Medium","High"},0)-1,0))>=5,0.4,IF((IFERROR(MATCH(Profiles!W6,{"None","Light","Medium","Heavy"},0)-1,0)+IFERROR(MATCH(Profiles!AB6,{"Low","Medium","High"},0)-1,0))>=4,0.6,IF((IFERROR(MATCH(Profiles!W6,{"None","Light","Medium","Heavy"},0)-1,0)+IFERROR(MATCH(Profiles!AB6,{"Low","Medium","High"},0)-1,0))>=3,0.75,IF((IFERROR(MATCH(Profiles!W6,{"None","Light","Medium","Heavy"},0)-1,0)+IFERROR(MATCH(Profiles!AB6,{"Low","Medium","High"},0)-1,0))>=2,0.85,1))))))) | Z5: =IF(OR('User Input'!$B$43="none",'User Input'!$B$43=""),1,IF('User Input'!$B$43="minor",IF(IFERROR(MATCH(Profiles!W6,{"None","Light","Medium","Heavy"},0)-1,0)>=3,0.7,IF(IFERROR(MATCH(Profiles!W6,{"None","Light","Medium","Heavy"},0)-1,0)>=2,0.85,1)),IF('User Input'!$B$43="joint",IF(OR(IFERROR(MATCH(Profiles!W6,{"None","Light","Medium","Heavy"},0)-1,0)>=3,IFERROR(MATCH(Profiles!AB6,{"Low","Medium","High"},0)-1,0)>=2),0.5,IF(OR(IFERROR(MATCH(Profiles!W6,{"None","Light","Medium","Heavy"},0)-1,0)>=2,IFERROR(MATCH(Profiles!AB6,{"Low","Medium","High"},0)-1,0)>=1),0.75,1)),IF(OR(IFERROR(MATCH(Profiles!W6,{"None","Light","Medium","Heavy"},0)-1,0)>=2,IFERROR(MATCH(Profiles!AB6,{"Low","Medium","High"},0)-1,0)>=2),0.3,IF(OR(IFERROR(MATCH(Profiles!W6,{"None","Light","Medium","Heavy"},0)-1,0)>=1,IFERROR(MATCH(Profiles!AB6,{"Low","Medium","High"},0)-1,0)>=1),0.6,0.9)))))
A6: =Profiles!A7 | B6: =Profiles!B7 | C6: =Profiles!C7 | D6: =Profiles!D7 | E6: =IF(ISNUMBER(Profiles!E7),IF(ISNUMBER(Profiles!F7),MAX(0,1-(MAX(0,ABS('User Input'!$B$9-Profiles!E7)-Profiles!F7))/Profiles!F7/3),MAX(0,1-ABS('User Input'!$B$9-Profiles!E7)/(Profiles!E7*0.1)/3)),0.5) | F6: =IF(ISNUMBER(Profiles!G7),IF(ISNUMBER(Profiles!H7),MAX(0,1-(MAX(0,ABS('User Input'!$B$10-Profiles!G7)-Profiles!H7))/Profiles!H7/3),MAX(0,1-ABS('User Input'!$B$10-Profiles!G7)/(Profiles!G7*0.15)/3)),0.5) | G6: =IF(ISNUMBER(Profiles!J7),MAX(0,1-ABS('User Input'!$B$12-Profiles!J7)/5/3),0.5) | H6: =IF(ISNUMBER(Profiles!K7),MAX(0,1-ABS('User Input'!$B$14-Profiles!K7)/0.03/3),"n/a") | I6: =100*MAX(0,1-(MAX(0,Profiles!M7-'User Input'!$B$17)+0.5*MAX(0,'User Input'!$B$17-Profiles!M7)+MAX(0,Profiles!N7-'User Input'!$B$18)+0.5*MAX(0,'User Input'!$B$18-Profiles!N7)+MAX(0,Profiles!O7-'User Input'!$B$19)+0.5*MAX(0,'User Input'!$B$19-Profiles!O7)+MAX(0,Profiles!P7-'User Input'!$B$20)+0.5*MAX(0,'User Input'!$B$20-Profiles!P7)+MAX(0,Profiles!Q7-'User Input'!$B$21)+0.5*MAX(0,'User Input'!$B$21-Profiles!Q7)+MAX(0,Profiles!S7-'User Input'!$B$22)+0.5*MAX(0,'User Input'!$B$22-Profiles!S7)+MAX(0,Profiles!T7-'User Input'!$B$23)+0.5*MAX(0,'User Input'!$B$23-Profiles!T7)+MAX(0,Profiles!U7-'User Input'!$B$24)+0.5*MAX(0,'User Input'!$B$24-Profiles!U7))/40) | J6: =ROUND(60*(E6+F6+G6+IFERROR(VALUE(H6),(E6+F6+G6)/3))/4 + 0.4*I6,1) | K6: =IF(OR(AND('User Input'!$B$6="M",Profiles!$AG7="M"),AND('User Input'!$B$6="F",Profiles!$AG7="F")),1,0) | L6: =IF('User Input'!$B$27="Either",(IF(Profiles!V7>=4,1,0.3)+IF(OR(Profiles!V7<=2,ISNUMBER(SEARCH("Individual",Profiles!D7))),1,0.3))/2,IF('User Input'!$B$27="Team",IF(Profiles!V7>=4,1,0.3),IF(OR(Profiles!V7<=2,ISNUMBER(SEARCH("Individual",Profiles!D7))),1,0.3))) | M6: =IF(IFERROR(MATCH(Profiles!W7,{"None","Light","Medium","Heavy"},0)-1,0)<=IFERROR(MATCH('User Input'!$B$28,{"None","Light","Medium","Heavy"},0)-1,3),1,MAX(0,1-0.4*(IFERROR(MATCH(Profiles!W7,{"None","Light","Medium","Heavy"},0)-1,0)-IFERROR(MATCH('User Input'!$B$28,{"None","Light","Medium","Heavy"},0)-1,3)))) | N6: =IF('User Input'!$B$29="neutral",1,IF('User Input'!$B$29="essential",IF(ISNUMBER(SEARCH("Outdoor",Profiles!X7)),1,0.3),IF('User Input'!$B$29="nice",IF(ISNUMBER(SEARCH("Outdoor",Profiles!X7)),1,0.65),IF('User Input'!$B$29="indoor",IF(ISNUMBER(SEARCH("Indoor",Profiles!X7)),1,0.4),1)))) | O6: =IF('User Input'!$B$30="Yes",1,IF(Profiles!Y7="Yes",0,1)) | P6: =IF(IFERROR(MATCH(Profiles!Z7,{"Low","Medium","High"},0),2)<=IFERROR(MATCH('User Input'!$B$31,{"Low","Medium","High"},0),2),1,MAX(0,1-0.4*(IFERROR(MATCH(Profiles!Z7,{"Low","Medium","High"},0),2)-IFERROR(MATCH('User Input'!$B$31,{"Low","Medium","High"},0),2)))) | Q6: =IF('User Input'!$B$32="Yes",IF(ISNUMBER(Profiles!AC7),Profiles!AC7/10,0.5),1) | R6: =IF(OR(K6=0,O6=0),0,ROUND(MIN(100,100*(K6*0.1+L6*0.2+M6*0.2+N6*0.1+P6*0.15+Q6*0.25)*W6*X6*Y6*Z6),1)) | S6: =IF(R6=0,0,ROUND(0.5*J6+0.5*R6,1)) | T6: =J6-ROW()/1000000 | U6: =R6-ROW()/1000000 | V6: =S6-ROW()/1000000 | W6: =IF(OR(AND(OR(Profiles!D7="Team field",Profiles!D7="Team field contact",Profiles!D7="Team field stick"),'User Input'!$B$34="Yes"),AND(OR(Profiles!D7="Team court",Profiles!D7="Team court contact"),'User Input'!$B$35="Yes"),AND(Profiles!D7="Individual racquet",'User Input'!$B$36="Yes"),AND(OR(Profiles!D7="Combat striking",Profiles!D7="Combat grappling",Profiles!D7="Combat mixed"),'User Input'!$B$37="Yes"),AND(OR(Profiles!D7="Team water contact",Profiles!D7="Individual water"),'User Input'!$B$38="Yes"),AND(OR(Profiles!D7="Endurance individual",Profiles!D7="Endurance individual / pair",Profiles!D7="Endurance individual / pursuit",Profiles!D7="Endurance team / pair",Profiles!D7="Endurance multi"),'User Input'!$B$39="Yes"),AND(OR(Profiles!D7="Strength individual",Profiles!D7="Power-throw individual"),'User Input'!$B$40="Yes"),AND(OR(Profiles!D7="Individual technical",Profiles!D7="Individual aesthetic",Profiles!D7="Team precision"),'User Input'!$B$41="Yes")),1.15,1) | X6: =IF('User Input'!$B$33<>"none",1,IF(IFERROR(VALUE(TRIM(MID(SUBSTITUTE(SUBSTITUTE(Profiles!AA7,"–","-"),"-",REPT(" ",100)),100,100)))<=14,FALSE),0.7,1)) | Y6: =IF(OR('User Input'!$B$42="under30",'User Input'!$B$42=""),1,IF('User Input'!$B$42="30to45",IF((IFERROR(MATCH(Profiles!W7,{"None","Light","Medium","Heavy"},0)-1,0)+IFERROR(MATCH(Profiles!AB7,{"Low","Medium","High"},0)-1,0))>=5,0.85,1),IF('User Input'!$B$42="46to60",IF((IFERROR(MATCH(Profiles!W7,{"None","Light","Medium","Heavy"},0)-1,0)+IFERROR(MATCH(Profiles!AB7,{"Low","Medium","High"},0)-1,0))>=5,0.65,IF((IFERROR(MATCH(Profiles!W7,{"None","Light","Medium","Heavy"},0)-1,0)+IFERROR(MATCH(Profiles!AB7,{"Low","Medium","High"},0)-1,0))>=4,0.8,IF((IFERROR(MATCH(Profiles!W7,{"None","Light","Medium","Heavy"},0)-1,0)+IFERROR(MATCH(Profiles!AB7,{"Low","Medium","High"},0)-1,0))>=3,0.9,1))),IF((IFERROR(MATCH(Profiles!W7,{"None","Light","Medium","Heavy"},0)-1,0)+IFERROR(MATCH(Profiles!AB7,{"Low","Medium","High"},0)-1,0))>=5,0.4,IF((IFERROR(MATCH(Profiles!W7,{"None","Light","Medium","Heavy"},0)-1,0)+IFERROR(MATCH(Profiles!AB7,{"Low","Medium","High"},0)-1,0))>=4,0.6,IF((IFERROR(MATCH(Profiles!W7,{"None","Light","Medium","Heavy"},0)-1,0)+IFERROR(MATCH(Profiles!AB7,{"Low","Medium","High"},0)-1,0))>=3,0.75,IF((IFERROR(MATCH(Profiles!W7,{"None","Light","Medium","Heavy"},0)-1,0)+IFERROR(MATCH(Profiles!AB7,{"Low","Medium","High"},0)-1,0))>=2,0.85,1))))))) | Z6: =IF(OR('User Input'!$B$43="none",'User Input'!$B$43=""),1,IF('User Input'!$B$43="minor",IF(IFERROR(MATCH(Profiles!W7,{"None","Light","Medium","Heavy"},0)-1,0)>=3,0.7,IF(IFERROR(MATCH(Profiles!W7,{"None","Light","Medium","Heavy"},0)-1,0)>=2,0.85,1)),IF('User Input'!$B$43="joint",IF(OR(IFERROR(MATCH(Profiles!W7,{"None","Light","Medium","Heavy"},0)-1,0)>=3,IFERROR(MATCH(Profiles!AB7,{"Low","Medium","High"},0)-1,0)>=2),0.5,IF(OR(IFERROR(MATCH(Profiles!W7,{"None","Light","Medium","Heavy"},0)-1,0)>=2,IFERROR(MATCH(Profiles!AB7,{"Low","Medium","High"},0)-1,0)>=1),0.75,1)),IF(OR(IFERROR(MATCH(Profiles!W7,{"None","Light","Medium","Heavy"},0)-1,0)>=2,IFERROR(MATCH(Profiles!AB7,{"Low","Medium","High"},0)-1,0)>=2),0.3,IF(OR(IFERROR(MATCH(Profiles!W7,{"None","Light","Medium","Heavy"},0)-1,0)>=1,IFERROR(MATCH(Profiles!AB7,{"Low","Medium","High"},0)-1,0)>=1),0.6,0.9)))))
